Workbook

Sheet Layanan Diskominfo
A1: No. | B1: ID PELANGGAN | C1: SERVICE ID | D1: NAMA PELANGGAN | E1: NPWP | F1: NOMOR KONTRAK | G1: PERIODE KONTRAK | H1: NOMOR KONTRAK LAMA | I1: KETERANGAN KONTRAK | J1: LAYANAN | K1: PRODUK | L1: NOMOR AL | M1: JENIS MUTASI | N1: TANGGAL MUTASI | O1: BILLING CUT OFF | P1: ALAMAT TERMINATING | Q1: TERMINASI | R1: PORT | S1: STATUS PORT | T1: KET | U1: SBU TERMINATING | V1: KP TERMINATING | W1: ALAMAT ORIGINATING | X1: SBU ORIGINATING | Y1: KP ORIGINATING | Z1: ID PERUSAHAAN | AA1: ID SAP | AB1: NO AX | AC1: NOMOR VA / REKENING | AD1: NAMA SAP | AE1: STATUS AKTIF | AF1: STATUS ISOLIR | AG1: HARGA LAYANAN | AH1: HARGA INSTALASI | AI1: ID TAGIHAN | AJ1: ID INVOICE | AK1: TGL INVOICE | AL1: PERIODE INVOICE | AM1: TIPE TAGIHAN | AN1: SIKLUS BILLING | AO1: TIPE PELANGGAN | AP1: JADWAL PENAGIHAN | AQ1: BIDANG REVENUE | AR1: SUB BIDANG REVENUE | AS1: SEGMEN ICON | AT1: SEGMEN CUSTOMER | AU1: REGIONAL | AV1: KANTOR PERWAKILAN
A2: 1 | B2: 311490003398 | C2: 311202004727 | D2: DISKOMINFO KOTA SINGKAWANG | E2: 00.280.304.7-702.000 | F2: EP-01KEQYM0J4BDVEGR7W4RWTXKST | G2: 2026/02/16 - 2026/12/31 | H2: - | I2: INTERNET DEDICATED DAN JARINGAN METRONET | J2: METRONET | K2: METRONET | L2: - | M2: AKTIVASI | N2: 46069 | O2: 46054 | P2: [311202004340] PUSKESMAS SINGKAWANG TENGAH 2 - JL AHMAD YANI | Q2: RKAL-MINI.ODC.UP3.SINGKAWANG-BD.2928-CPE-01 | R2: g0/8 | S2: Down | T2: Perangkat Hilang | U2: KALIMANTAN | V2: KALIMANTAN BARAT | W2: DISKOMINFO KOTA SINGKAWANG - JL. AHMAD YANI NO. 76 | X2: KALIMANTAN | Y2: KALIMANTAN BARAT | Z2: 26671 | AA2: 200005426 | AB2: 140001941 | AC2: - | AD2: - | AE2: AKTIF | AF2: UNISOLIR | AG2: 0,00 | AH2: 0,00 | AI2: - | AJ2: 90391497 | AK2: --/--/-- | AL2: 2026/03/01 - 2026/03/31 | AM2: PREPAID | AN2: PRORATE | AO2: SUBSCRIBE | AP2: 1 - BULAN | AQ2: KALIMANTAN | AR2: KALIMANTAN BARAT | AS2: GOVERNMENT | AT2: GOVERNMENT | AU2: KALIMANTAN | AV2: KALIMANTAN TIMUR
A3: 2 | B3: 311490003398 | C3: 311202004728 | D3: DISKOMINFO KOTA SINGKAWANG | E3: 00.280.304.7-702.000 | F3: EP-01KEQYM0J4BDVEGR7W4RWTXKST | G3: 2026/02/16 - 2026/12/31 | H3: - | I3: INTERNET DEDICATED DAN JARINGAN METRONET | J3: METRONET | K3: METRONET | L3: - | M3: AKTIVASI | N3: 46069 | O3: 46054 | P3: [311202004359] DINAS KESEHATAN DAN KELUARGA BERENCANA - JL. ALIANYANG NO. 7 | Q3: RKAL-DISKOMINFO.KOTA.SINGKAWANG-ZYXEL.MGS3520-CPE-02 | R3: e 0/0/12 | S3: Up | T3: ok | U3: KALIMANTAN | V3: KALIMANTAN BARAT | W3: DISKOMINFO KOTA SINGKAWANG - JL. AHMAD YANI NO. 76 | X3: KALIMANTAN | Y3: KALIMANTAN BARAT | Z3: 26671 | AA3: 200005426 | AB3: 140001941 | AC3: - | AD3: - | AE3: AKTIF | AF3: UNISOLIR | AG3: 0,00 | AH3: 0,00 | AI3: - | AJ3: 90379451 | AK3: --/--/-- | AL3: 2026/03/01 - 2026/03/31 | AM3: PREPAID | AN3: PRORATE | AO3: SUBSCRIBE | AP3: 1 - BULAN | AQ3: KALIMANTAN | AR3: KALIMANTAN BARAT | AS3: GOVERNMENT | AT3: GOVERNMENT | AU3: KALIMANTAN | AV3: KALIMANTAN TIMUR
A4: 3 | B4: 311490003398 | C4: 311202004731 | D4: DISKOMINFO KOTA SINGKAWANG | E4: 00.280.304.7-702.000 | F4: EP-01KEQYM0J4BDVEGR7W4RWTXKST | G4: 2026/02/16 - 2026/12/31 | H4: - | I4: INTERNET DEDICATED DAN JARINGAN METRONET | J4: METRONET | K4: METRONET | L4: - | M4: AKTIVASI | N4: 46069 | O4: 46054 | P4: [311202004355] CCTV SEI WIE - JL. ALIANYANG, SEI WEI | Q4: RKAL-DISKOMINFO.KOTA.SINGKAWANG-ZYXEL.MGS3520-CPE-03 | R4: e0/0/20 | S4: Up | T4: ok | U4: KALIMANTAN | V4: KALIMANTAN BARAT | W4: DISKOMINFO KOTA SINGKAWANG - JL. AHMAD YANI NO. 76 | X4: KALIMANTAN | Y4: KALIMANTAN BARAT | Z4: 26671 | AA4: 200005426 | AB4: 140001941 | AC4: - | AD4: - | AE4: AKTIF | AF4: UNISOLIR | AG4: 0,00 | AH4: 0,00 | AI4: - | AJ4: 90455416 | AK4: --/--/-- | AL4: 2026/03/01 - 2026/03/31 | AM4: PREPAID | AN4: PRORATE | AO4: SUBSCRIBE | AP4: 1 - BULAN | AQ4: KALIMANTAN | AR4: KALIMANTAN BARAT | AS4: GOVERNMENT | AT4: GOVERNMENT | AU4: KALIMANTAN | AV4: KALIMANTAN TIMUR
A5: 2 | B5: 311490003398 | C5: 311202004730 | D5: DISKOMINFO KOTA SINGKAWANG | E5: 00.280.304.7-702.000 | F5: EP-01KEQYM0J4BDVEGR7W4RWTXKST | G5: 2026/02/16 - 2026/12/31 | H5: - | I5: INTERNET DEDICATED DAN JARINGAN METRONET | J5: METRONET | K5: METRONET | L5: - | M5: AKTIVASI | N5: 46069 | O5: 46054 | P5: [311202004354] DINAS PERDAGANGAN, PERINDUSTRIAN, KOPERASI DAN UKM - JL. FIRDAUS | Q5: RKAL-DISKOMINFO.KOTA.SINGKAWANG-ZYXEL.MGS3520-CPE-02 | R5: e 0/0/10 | S5: Down | T5: Digunakan -Hasil OPM kearah mikrotik -2.99 dbm, -Hasil OPM kearah HO Low indikasi fo cut -Mikrotik nyala, tidak ada UTP yang ke colok, -Hasil OTDR ke arah HO putus di 2.19 Km dari user | U5: KALIMANTAN | V5: KALIMANTAN BARAT | W5: DISKOMINFO KOTA SINGKAWANG - JL. AHMAD YANI NO. 76 | X5: KALIMANTAN | Y5: KALIMANTAN BARAT | Z5: 26671 | AA5: 200005426 | AB5: 140001941 | AC5: - | AD5: - | AE5: AKTIF | AF5: UNISOLIR | AG5: 0,00 | AH5: 0,00 | AI5: - | AJ5: 90364259 | AK5: --/--/-- | AL5: 2026/03/01 - 2026/03/31 | AM5: PREPAID | AN5: PRORATE | AO5: SUBSCRIBE | AP5: 1 - BULAN | AQ5: KALIMANTAN | AR5: KALIMANTAN BARAT | AS5: GOVERNMENT | AT5: GOVERNMENT | AU5: KALIMANTAN | AV5: KALIMANTAN TIMUR
A6: 5 | B6: 311490003398 | C6: 311202004732 | D6: DISKOMINFO KOTA SINGKAWANG | E6: 00.280.304.7-702.000 | F6: EP-01KEQYM0J4BDVEGR7W4RWTXKST | G6: 2026/02/16 - 2026/12/31 | H6: - | I6: INTERNET DEDICATED DAN JARINGAN METRONET | J6: METRONET | K6: METRONET | L6: - | M6: AKTIVASI | N6: 46069 | O6: 46054 | P6: [311202004356] DINAS PERHUBUNGAN - JL. TERMINAL INDUK SEI WIE | Q6: RKAL-DISKOMINFO.KOTA.SINGKAWANG-ZYXEL.MGS3520-CPE-03 | R6: e0/0/15 | S6: Up | T6: ok | U6: KALIMANTAN | V6: KALIMANTAN BARAT | W6: DISKOMINFO KOTA SINGKAWANG - JL. AHMAD YANI NO. 76 | X6: KALIMANTAN | Y6: KALIMANTAN BARAT | Z6: 26671 | AA6: 200005426 | AB6: 140001941 | AC6: - | AD6: - | AE6: AKTIF | AF6: UNISOLIR | AG6: 0,00 | AH6: 0,00 | AI6: - | AJ6: 90400809 | AK6: --/--/-- | AL6: 2026/03/01 - 2026/03/31 | AM6: PREPAID | AN6: PRORATE | AO6: SUBSCRIBE | AP6: 1 - BULAN | AQ6: KALIMANTAN | AR6: KALIMANTAN BARAT | AS6: GOVERNMENT | AT6: GOVERNMENT | AU6: KALIMANTAN | AV6: KALIMANTAN TIMUR
A7: 6 | B7: 311490003398 | C7: 311202004682 | D7: DISKOMINFO KOTA SINGKAWANG | E7: 00.280.304.7-702.000 | F7: EP-01KEQYM0J4BDVEGR7W4RWTXKST | G7: 2026/02/16 - 2026/12/31 | H7: - | I7: INTERNET DEDICATED DAN JARINGAN METRONET | J7: METRONET | K7: METRONET | L7: - | M7: AKTIVASI | N7: 46069 | O7: 46054 | P7: [311202004357] CCTV HERMANSYAH - JL. S.M TSJAFIOEDDIN 17-51 | Q7: RKAL-DISKOMINFO.KOTA.SINGKAWANG-ZYXEL.MGS3520-CPE-03 | R7: e0/0/19 | S7: Up | T7: ok | U7: KALIMANTAN | V7: KALIMANTAN BARAT | W7: DISKOMINFO KOTA SINGKAWANG - JL. AHMAD YANI NO. 76 | X7: KALIMANTAN | Y7: KALIMANTAN BARAT | Z7: 26671 | AA7: 200005426 | AB7: 140001941 | AC7: - | AD7: - | AE7: AKTIF | AF7: UNISOLIR | AG7: 0,00 | AH7: 0,00 | AI7: - | AJ7: 90448245 | AK7: --/--/-- | AL7: 2026/03/01 - 2026/03/31 | AM7: PREPAID | AN7: PRORATE | AO7: SUBSCRIBE | AP7: 1 - BULAN | AQ7: KALIMANTAN | AR7: KALIMANTAN BARAT | AS7: GOVERNMENT | AT7: GOVERNMENT | AU7: KALIMANTAN | AV7: KALIMANTAN TIMUR
A8: 3 | B8: 311490003398 | C8: 311202004733 | D8: DISKOMINFO KOTA SINGKAWANG | E8: 00.280.304.7-702.000 | F8: EP-01KEQYM0J4BDVEGR7W4RWTXKST | G8: 2026/02/16 - 2026/12/31 | H8: - | I8: INTERNET DEDICATED DAN JARINGAN METRONET | J8: METRONET | K8: METRONET | L8: - | M8: AKTIVASI | N8: 46069 | O8: 46054 | P8: [311202004351] SEKRETARIAT DPRD - JL. FIRDAUS | Q8: RKAL-DISKOMINFO.KOTA.SINGKAWANG-ZYXEL.MGS3520-CPE-02 | R8: e 0/0/20 | S8: Down | T8: Info User OPD tidak digunakan - perangkat sudah diambil Kominfo - Kabel Putus Impact renovasi gedung | U8: KALIMANTAN | V8: KALIMANTAN BARAT | W8: DISKOMINFO KOTA SINGKAWANG - JL. AHMAD YANI NO. 76 | X8: KALIMANTAN | Y8: KALIMANTAN BARAT | Z8: 26671 | AA8: 200005426 | AB8: 140001941 | AC8: - | AD8: - | AE8: AKTIF | AF8: UNISOLIR | AG8: 0,00 | AH8: 0,00 | AI8: - | AJ8: 90364260 | AK8: --/--/-- | AL8: 2026/03/01 - 2026/03/31 | AM8: PREPAID | AN8: PRORATE | AO8: SUBSCRIBE | AP8: 1 - BULAN | AQ8: KALIMANTAN | AR8: KALIMANTAN BARAT | AS8: GOVERNMENT | AT8: GOVERNMENT | AU8: KALIMANTAN | AV8: KALIMANTAN TIMUR
A9: 4 | B9: 311490003398 | C9: 311202004734 | D9: DISKOMINFO KOTA SINGKAWANG | E9: 00.280.304.7-702.000 | F9: EP-01KEQYM0J4BDVEGR7W4RWTXKST | G9: 2026/02/16 - 2026/12/31 | H9: - | I9: INTERNET DEDICATED DAN JARINGAN METRONET | J9: METRONET | K9: METRONET | L9: - | M9: AKTIVASI | N9: 46069 | O9: 46054 | P9: [311202004352] DINAS PENANAMAN MODAL DAN TENAGA KERJA - JL. BKLI KOMPLEK LLK-UKM | Q9: RKAL-DISKOMINFO.KOTA.SINGKAWANG-ZYXEL.MGS3520-CPE-02 | R9: e 0/0/9 | S9: Down | T9: tidak Digunakan | U9: KALIMANTAN | V9: KALIMANTAN BARAT | W9: DISKOMINFO KOTA SINGKAWANG - JL. AHMAD YANI NO. 76 | X9: KALIMANTAN | Y9: KALIMANTAN BARAT | Z9: 26671 | AA9: 200005426 | AB9: 140001941 | AC9: - | AD9: - | AE9: AKTIF | AF9: UNISOLIR | AG9: 0,00 | AH9: 0,00 | AI9: - | AJ9: 90400811 | AK9: --/--/-- | AL9: 2026/03/01 - 2026/03/31 | AM9: PREPAID | AN9: PRORATE | AO9: SUBSCRIBE | AP9: 1 - BULAN | AQ9: KALIMANTAN | AR9: KALIMANTAN BARAT | AS9: GOVERNMENT | AT9: GOVERNMENT | AU9: KALIMANTAN | AV9: KALIMANTAN TIMUR
A10: 5 | B10: 311490003398 | C10: 311202004729 | D10: DISKOMINFO KOTA SINGKAWANG | E10: 00.280.304.7-702.000 | F10: EP-01KEQYM0J4BDVEGR7W4RWTXKST | G10: 2026/02/16 - 2026/12/31 | H10: - | I10: INTERNET DEDICATED DAN JARINGAN METRONET | J10: METRONET | K10: METRONET | L10: - | M10: AKTIVASI | N10: 46069 | O10: 46054 | P10: [311202004360] KANTOR KELURAHAN SEJANGKUNG - JL. RAYA SEJANGKUNG | Q10: RKAL-DISKOMINFO.KOTA.SINGKAWANG-ZYXEL.MGS3520-CPE-03 | R10: e0/0/9 | S10: Down | T10: Perangkat Tidak ada | U10: KALIMANTAN | V10: KALIMANTAN BARAT | W10: - | X10: - | Y10: - | Z10: 26671 | AA10: 200005426 | AB10: 140001941 | AC10: - | AD10: - | AE10: AKTIF | AF10: UNISOLIR | AG10: 0,00 | AH10: 0,00 | AI10: - | AJ10: 90450968 | AK10: --/--/-- | AL10: 2026/03/01 - 2026/03/31 | AM10: PREPAID | AN10: PRORATE | AO10: SUBSCRIBE | AP10: 1 - BULAN | AQ10: KALIMANTAN | AR10: KALIMANTAN BARAT | AS10: GOVERNMENT | AT10: GOVERNMENT | AU10: KALIMANTAN | AV10: KALIMANTAN TIMUR
A11: 10 | B11: 311490003398 | C11: 311202004684 | D11: DISKOMINFO KOTA SINGKAWANG | E11: 00.280.304.7-702.000 | F11: EP-01KEQYM0J4BDVEGR7W4RWTXKST | G11: 2026/02/16 - 2026/12/31 | H11: - | I11: INTERNET DEDICATED DAN JARINGAN METRONET | J11: METRONET | K11: METRONET | L11: - | M11: AKTIVASI | N11: 46069 | O11: 46054 | P11: [311202004361] KANTOR KELURAHAN PANGMILANG - PANGMILANG | Q11: RKAL-DISKOMINFO.KOTA.SINGKAWANG-ZYXEL.MGS3520-CPE-03 | R11: e0/0/10 | S11: Up | T11: ok | U11: KALIMANTAN | V11: KALIMANTAN BARAT | W11: - | X11: - | Y11: - | Z11: 26671 | AA11: 200005426 | AB11: 140001941 | AC11: - | AD11: - | AE11: AKTIF | AF11: UNISOLIR | AG11: 0,00 | AH11: 0,00 | AI11: - | AJ11: 90400813 | AK11: --/--/-- | AL11: 2026/03/01 - 2026/03/31 | AM11: PREPAID | AN11: PRORATE | AO11: SUBSCRIBE | AP11: 1 - BULAN | AQ11: KALIMANTAN | AR11: KALIMANTAN BARAT | AS11: GOVERNMENT | AT11: GOVERNMENT | AU11: KALIMANTAN | AV11: KALIMANTAN TIMUR
A12: 6 | B12: 311490003398 | C12: 311202004685 | D12: DISKOMINFO KOTA SINGKAWANG | E12: 00.280.304.7-702.000 | F12: EP-01KEQYM0J4BDVEGR7W4RWTXKST | G12: 2026/02/16 - 2026/12/31 | H12: - | I12: INTERNET DEDICATED DAN JARINGAN METRONET | J12: METRONET | K12: METRONET | L12: - | M12: AKTIVASI | N12: 46069 | O12: 46054 | P12: [311202004362] KANTOR KELURAHAN SEDAU - JL. RAYA SEDAU | Q12: RKAL-DISKOMINFO.KOTA.SINGKAWANG-ZYXEL.MGS3520-CPE-03 | R12: e0/0/6 | S12: Down | T12: Perangkat Ada | U12: KALIMANTAN | V12: KALIMANTAN BARAT | W12: - | X12: - | Y12: - | Z12: 26671 | AA12: 200005426 | AB12: 140001941 | AC12: - | AD12: - | AE12: AKTIF | AF12: UNISOLIR | AG12: 0,00 | AH12: 0,00 | AI12: - | AJ12: 90363054 | AK12: --/--/-- | AL12: 2026/03/01 - 2026/03/31 | AM12: PREPAID | AN12: PRORATE | AO12: SUBSCRIBE | AP12: 1 - BULAN | AQ12: KALIMANTAN | AR12: KALIMANTAN BARAT | AS12: GOVERNMENT | AT12: GOVERNMENT | AU12: KALIMANTAN | AV12: KALIMANTAN TIMUR
A13: 12 | B13: 311490003398 | C13: 311202004686 | D13: DISKOMINFO KOTA SINGKAWANG | E13: 00.280.304.7-702.000 | F13: EP-01KEQYM0J4BDVEGR7W4RWTXKST | G13: 2026/02/16 - 2026/12/31 | H13: - | I13: INTERNET DEDICATED DAN JARINGAN METRONET | J13: METRONET | K13: METRONET | L13: - | M13: AKTIVASI | N13: 46069 | O13: 46054 | P13: [311202004363] KANTOR KELURAHAN SAGATANI - JL. SAGATANI | Q13: RKAL-DISKOMINFO.KOTA.SINGKAWANG-ZYXEL.MGS3520-CPE-03 | R13: e0/0/7 | S13: Up | T13: ok | U13: KALIMANTAN | V13: KALIMANTAN BARAT | W13: - | X13: - | Y13: - | Z13: 26671 | AA13: 200005426 | AB13: 140001941 | AC13: - | AD13: - | AE13: AKTIF | AF13: UNISOLIR | AG13: 0,00 | AH13: 0,00 | AI13: - | AJ13: 90364261 | AK13: --/--/-- | AL13: 2026/03/01 - 2026/03/31 | AM13: PREPAID | AN13: PRORATE | AO13: SUBSCRIBE | AP13: 1 - BULAN | AQ13: KALIMANTAN | AR13: KALIMANTAN BARAT | AS13: GOVERNMENT | AT13: GOVERNMENT | AU13: KALIMANTAN | AV13: KALIMANTAN TIMUR
... A25: 24 | B25: 311490003398 | C25: 311202004706 | D25: - | E25: 00.280.304.7-702.000 | F25: EP-01KEQYM0J4BDVEGR7W4RWTXKST | G25: 2026/02/16 - 2026/12/31 | H25: - | I25: INTERNET DEDICATED DAN JARINGAN METRONET | J25: METRONET | K25: METRONET | L25: - | M25: AKTIVASI | N25: 46069 | O25: 46054 | P25: [311202004383] CCTV PERBATASAN SAMBAS - JL. PASAR SEMELAGI BESAR | Q25: RKAL-SHELTER.GI.SINGKAWANG-ASR920-UPE-01 | R25: Gi0/0/20 | S25: Up | T25: ok | U25: KALIMANTAN | V25: KALIMANTAN BARAT | W25: - | X25: - | Y25: - | Z25: 26671 | AA25: 200005426 | AB25: 140001941 | AC25: - | AD25: - | AE25: AKTIF | AF25: UNISOLIR | AG25: 0,00 | AH25: 0,00 | AI25: - | AJ25: 90460029 | AK25: --/--/-- | AL25: 2026/03/01 - 2026/03/31 | AM25: PREPAID | AN25: PRORATE | AO25: SUBSCRIBE | AP25: 1 - BULAN | AQ25: KALIMANTAN | AR25: KALIMANTAN BARAT | AS25: GOVERNMENT | AT25: GOVERNMENT | AU25: KALIMANTAN | AV25: KALIMANTAN TIMUR
A26: 2 | B26: 311490003398 | C26: 311601002733 | D26: DISKOMINFO KOTA SINGKAWANG | E26: 00.280.304.7-702.000 | F26: EP-01KEQYM0J4BDVEGR7W4RWTXKST | G26: 2026/02/16 - 2026/12/31 | H26: - | I26: INTERNET DEDICATED DAN JARINGAN METRONET | J26: MANAGE SERVICE ROUTER | K26: MANAGE SERVICE ROUTER BRONZE | L26: - | M26: AKTIVASI | N26: 46069 | O26: 46054 | P26: [311601002581] PUSKESMAS SINGKAWANG TENGAH 1 - JL. SALAM DIMAN | R26: ge1/0/2 | S26: Down | T26: Perangkat Hilang | U26: KALIMANTAN | V26: KALIMANTAN BARAT | W26: - | X26: - | Y26: - | Z26: 26671 | AA26: 200005426 | AB26: 140001941 | AC26: - | AD26: - | AE26: AKTIF | AF26: UNISOLIR | AG26: 0,00 | AH26: 0,00 | AI26: - | AJ26: 90400816 | AK26: --/--/-- | AL26: 2026/03/01 - 2026/03/31 | AM26: PREPAID | AN26: PRORATE | AO26: SUBSCRIBE | AP26: 1 - BULAN | AQ26: KALIMANTAN | AR26: KALIMANTAN BARAT | AS26: GOVERNMENT | AT26: GOVERNMENT | AU26: KALIMANTAN | AV26: KALIMANTAN TIMUR
A27: 3 | B27: 311490003398 | C27: 311601002734 | D27: DISKOMINFO KOTA SINGKAWANG | E27: 00.280.304.7-702.000 | F27: EP-01KEQYM0J4BDVEGR7W4RWTXKST | G27: 2026/02/16 - 2026/12/31 | H27: - | I27: INTERNET DEDICATED DAN JARINGAN METRONET | J27: MANAGE SERVICE ROUTER | K27: MANAGE SERVICE ROUTER BRONZE | L27: - | M27: AKTIVASI | N27: 46069 | O27: 46054 | P27: [311601002582] PUSKESMAS SINGKAWANG TENGAH 2 - JL. SUNGAI BARITO | R27: - | S27: Down | T27: Perangkat Hilang | U27: KALIMANTAN | V27: KALIMANTAN BARAT | W27: - | X27: - | Y27: - | Z27: 26671 | AA27: 200005426 | AB27: 140001941 | AC27: - | AD27: - | AE27: AKTIF | AF27: UNISOLIR | AG27: 0,00 | AH27: 0,00 | AI27: - | AJ27: 90451982 | AK27: --/--/-- | AL27: 2026/03/01 - 2026/03/31 | AM27: PREPAID | AN27: PRORATE | AO27: SUBSCRIBE | AP27: 1 - BULAN | AQ27: KALIMANTAN | AR27: KALIMANTAN BARAT | AS27: GOVERNMENT | AT27: GOVERNMENT | AU27: KALIMANTAN | AV27: KALIMANTAN TIMUR
A28: 4 | B28: 311490003398 | C28: 311601002735 | D28: DISKOMINFO KOTA SINGKAWANG | E28: 00.280.304.7-702.000 | F28: EP-01KEQYM0J4BDVEGR7W4RWTXKST | G28: 2026/02/16 - 2026/12/31 | H28: - | I28: INTERNET DEDICATED DAN JARINGAN METRONET | J28: MANAGE SERVICE ROUTER | K28: MANAGE SERVICE ROUTER BRONZE | L28: - | M28: AKTIVASI | N28: 46069 | O28: 46054 | P28: [311601002583] PUSKESMAS SINGKAWANG BARAT 1 - JL. ALIANYANG | R28: - | S28: Down | T28: Perangkat Hilang | U28: KALIMANTAN | V28: KALIMANTAN BARAT | W28: - | X28: - | Y28: - | Z28: 26671 | AA28: 200005426 | AB28: 140001941 | AC28: - | AD28: - | AE28: AKTIF | AF28: UNISOLIR | AG28: 0,00 | AH28: 0,00 | AI28: - | AJ28: 90443563 | AK28: --/--/-- | AL28: 2026/03/01 - 2026/03/31 | AM28: PREPAID | AN28: PRORATE | AO28: SUBSCRIBE | AP28: 1 - BULAN | AQ28: KALIMANTAN | AR28: KALIMANTAN BARAT | AS28: GOVERNMENT | AT28: GOVERNMENT | AU28: KALIMANTAN | AV28: KALIMANTAN TIMUR
A29: 28 | B29: 311490003398 | C29: 311601002736 | D29: DISKOMINFO KOTA SINGKAWANG | E29: 00.280.304.7-702.000 | F29: EP-01KEQYM0J4BDVEGR7W4RWTXKST | G29: 2026/02/16 - 2026/12/31 | H29: - | I29: INTERNET DEDICATED DAN JARINGAN METRONET | J29: MANAGE SERVICE ROUTER | K29: MANAGE SERVICE ROUTER BRONZE | L29: - | M29: AKTIVASI | N29: 46069 | O29: 46054 | P29: [311601002584] PUSKESMAS SINGKAWANG TIMUR 2 - JL. RAYA SINGKAWANG-BENGKAYANG | R29: - | S29: Up | T29: Baru dikatifkan lagi bulan Mei 2026 | U29: KALIMANTAN | V29: KALIMANTAN BARAT | W29: - | X29: - | Y29: - | Z29: 26671 | AA29: 200005426 | AB29: 140001941 | AC29: - | AD29: - | AE29: AKTIF | AF29: UNISOLIR | AG29: 0,00 | AH29: 0,00 | AI29: - | AJ29: 90426363 | AK29: --/--/-- | AL29: 2026/03/01 - 2026/03/31 | AM29: PREPAID | AN29: PRORATE | AO29: SUBSCRIBE | AP29: 1 - BULAN | AQ29: KALIMANTAN | AR29: KALIMANTAN BARAT | AS29: GOVERNMENT | AT29: GOVERNMENT | AU29: KALIMANTAN | AV29: KALIMANTAN TIMUR
A30: 5 | B30: 311490003398 | C30: 311601002737 | D30: DISKOMINFO KOTA SINGKAWANG | E30: 00.280.304.7-702.000 | F30: EP-01KEQYM0J4BDVEGR7W4RWTXKST | G30: 2026/02/16 - 2026/12/31 | H30: - | I30: INTERNET DEDICATED DAN JARINGAN METRONET | J30: MANAGE SERVICE ROUTER | K30: MANAGE SERVICE ROUTER BRONZE | L30: - | M30: AKTIVASI | N30: 46069 | O30: 46054 | P30: [311601002585] PUSKESMAS SINGKAWANG TIMUR 1 - JL. RAYA PAJINTAN | R30: - | S30: Down | T30: Perangkat Hilang | U30: KALIMANTAN | V30: KALIMANTAN BARAT | W30: - | X30: - | Y30: - | Z30: 26671 | AA30: 200005426 | AB30: 140001941 | AC30: - | AD30: - | AE30: AKTIF | AF30: UNISOLIR | AG30: 0,00 | AH30: 0,00 | AI30: - | AJ30: 90460031 | AK30: --/--/-- | AL30: 2026/03/01 - 2026/03/31 | AM30: PREPAID | AN30: PRORATE | AO30: SUBSCRIBE | AP30: 1 - BULAN | AQ30: KALIMANTAN | AR30: KALIMANTAN BARAT | AS30: GOVERNMENT | AT30: GOVERNMENT | AU30: KALIMANTAN | AV30: KALIMANTAN TIMUR
A31: 6 | B31: 311490003398 | C31: 311601002738 | D31: DISKOMINFO KOTA SINGKAWANG | E31: 00.280.304.7-702.000 | F31: EP-01KEQYM0J4BDVEGR7W4RWTXKST | G31: 2026/02/16 - 2026/12/31 | H31: - | I31: INTERNET DEDICATED DAN JARINGAN METRONET | J31: MANAGE SERVICE ROUTER | K31: MANAGE SERVICE ROUTER BRONZE | L31: - | M31: AKTIVASI | N31: 46069 | O31: 46054 | P31: [311601002586] PUSKESMAS SINGKAWANG BARAT 2 - JL YOHANA | R31: - | S31: Down | T31: Perangkat Hilang | U31: KALIMANTAN | V31: KALIMANTAN BARAT | W31: - | X31: - | Y31: - | Z31: 26671 | AA31: 200005426 | AB31: 140001941 | AC31: - | AD31: - | AE31: AKTIF | AF31: UNISOLIR | AG31: 0,00 | AH31: 0,00 | AI31: - | AJ31: 90448252 | AK31: --/--/-- | AL31: 2026/03/01 - 2026/03/31 | AM31: PREPAID | AN31: PRORATE | AO31: SUBSCRIBE | AP31: 1 - BULAN | AQ31: KALIMANTAN | AR31: KALIMANTAN BARAT | AS31: GOVERNMENT | AT31: GOVERNMENT | AU31: KALIMANTAN | AV31: KALIMANTAN TIMUR
A32: 7 | B32: 311490003398 | C32: 311601002739 | D32: DISKOMINFO KOTA SINGKAWANG | E32: 00.280.304.7-702.000 | F32: EP-01KEQYM0J4BDVEGR7W4RWTXKST | G32: 2026/02/16 - 2026/12/31 | H32: - | I32: INTERNET DEDICATED DAN JARINGAN METRONET | J32: MANAGE SERVICE ROUTER | K32: MANAGE SERVICE ROUTER BRONZE | L32: - | M32: AKTIVASI | N32: 46069 | O32: 46054 | P32: [311601002587] PUSKESMAS SINGKAWANG UTARA 1 - JL RATU SEPUDAK | R32: - | S32: Down | T32: Perangkat Hilang | U32: KALIMANTAN | V32: KALIMANTAN BARAT | W32: - | X32: - | Y32: - | Z32: 26671 | AA32: 200005426 | AB32: 140001941 | AC32: - | AD32: - | AE32: AKTIF | AF32: UNISOLIR | AG32: 0,00 | AH32: 0,00 | AI32: - | AJ32: 90448254 | AK32: --/--/-- | AL32: 2026/03/01 - 2026/03/31 | AM32: PREPAID | AN32: PRORATE | AO32: SUBSCRIBE | AP32: 1 - BULAN | AQ32: KALIMANTAN | AR32: KALIMANTAN BARAT | AS32: GOVERNMENT | AT32: GOVERNMENT | AU32: KALIMANTAN | AV32: KALIMANTAN TIMUR
A33: 8 | B33: 311490003398 | C33: 311601002740 | D33: DISKOMINFO KOTA SINGKAWANG | E33: 00.280.304.7-702.000 | F33: EP-01KEQYM0J4BDVEGR7W4RWTXKST | G33: 2026/02/16 - 2026/12/31 | H33: - | I33: INTERNET DEDICATED DAN JARINGAN METRONET | J33: MANAGE SERVICE ROUTER | K33: MANAGE SERVICE ROUTER BRONZE | L33: - | M33: AKTIVASI | N33: 46069 | O33: 46054 | P33: [311601002588] PUSKESMAS SINGKAWANG UTARA 2 - JL. DEMANG AKUB | R33: - | S33: Down | T33: Perangkat Hilang | U33: KALIMANTAN | V33: KALIMANTAN BARAT | W33: - | X33: - | Y33: - | Z33: 26671 | AA33: 200005426 | AB33: 140001941 | AC33: - | AD33: - | AE33: AKTIF | AF33: UNISOLIR | AG33: 0,00 | AH33: 0,00 | AI33: - | AJ33: 90439902 | AK33: --/--/-- | AL33: 2026/03/01 - 2026/03/31 | AM33: PREPAID | AN33: PRORATE | AO33: SUBSCRIBE | AP33: 1 - BULAN | AQ33: KALIMANTAN | AR33: KALIMANTAN BARAT | AS33: GOVERNMENT | AT33: GOVERNMENT | AU33: KALIMANTAN | AV33: KALIMANTAN TIMUR
A34: 9 | B34: 311490003398 | C34: 311601002743 | D34: DISKOMINFO KOTA SINGKAWANG | E34: 00.280.304.7-702.000 | F34: EP-01KEQYM0J4BDVEGR7W4RWTXKST | G34: 2026/02/16 - 2026/12/31 | H34: - | I34: INTERNET DEDICATED DAN JARINGAN METRONET | J34: MANAGE SERVICE ROUTER | K34: MANAGE SERVICE ROUTER BRONZE | L34: - | M34: AKTIVASI | N34: 46069 | O34: 46054 | P34: [311601002591] DINAS PERUMAHAN PEMUKIMAN DAN PERTANAHAN - JL. AHMAD YANI NOMOR 74 | R34: - | S34: Down | T34: Info User OPD tidak digunakan -Kabel Putus, perangkat hilang karena pindah kantor/renovasi | U34: KALIMANTAN | V34: KALIMANTAN BARAT | W34: - | X34: - | Y34: - | Z34: 26671 | AA34: 200005426 | AB34: 140001941 | AC34: - | AD34: - | AE34: AKTIF | AF34: UNISOLIR | AG34: 0,00 | AH34: 0,00 | AI34: - | AJ34: 90392026 | AK34: --/--/-- | AL34: 2026/03/01 - 2026/03/31 | AM34: PREPAID | AN34: PRORATE | AO34: SUBSCRIBE | AP34: 1 - BULAN | AQ34: KALIMANTAN | AR34: KALIMANTAN BARAT | AS34: GOVERNMENT | AT34: GOVERNMENT | AU34: KALIMANTAN | AV34: KALIMANTAN TIMUR
A35: 34 | B35: 311490003398 | C35: 311601002744 | D35: DISKOMINFO KOTA SINGKAWANG | E35: 00.280.304.7-702.000 | F35: EP-01KEQYM0J4BDVEGR7W4RWTXKST | G35: 2026/02/16 - 2026/12/31 | H35: - | I35: INTERNET DEDICATED DAN JARINGAN METRONET | J35: MANAGE SERVICE ROUTER | K35: MANAGE SERVICE ROUTER BRONZE | L35: - | M35: AKTIVASI | N35: 46069 | O35: 46054 | P35: [311601002592] DINAS LINGKUNGAN HIDUP - JL. MERDEKA NO. 78 | R35: - | S35: Down | T35: Perangkat ada | U35: KALIMANTAN | V35: KALIMANTAN BARAT | W35: - | X35: - | Y35: - | Z35: 26671 | AA35: 200005426 | AB35: 140001941 | AC35: - | AD35: - | AE35: AKTIF | AF35: UNISOLIR | AG35: 0,00 | AH35: 0,00 | AI35: - | AJ35: 90443565 | AK35: --/--/-- | AL35: 2026/03/01 - 2026/03/31 | AM35: PREPAID | AN35: PRORATE | AO35: SUBSCRIBE | AP35: 1 - BULAN | AQ35: KALIMANTAN | AR35: KALIMANTAN BARAT | AS35: GOVERNMENT | AT35: GOVERNMENT | AU35: KALIMANTAN | AV35: KALIMANTAN TIMUR
A36: 35 | B36: 311490003398 | C36: 311601002779 | D36: - | E36: 00.280.304.7-702.000 | F36: EP-01KEQYM0J4BDVEGR7W4RWTXKST | G36: 2026/02/16 - 2026/12/31 | H36: - | I36: INTERNET DEDICATED DAN JARINGAN METRONET | J36: MANAGE SERVICE ROUTER | K36: MANAGE SERVICE ROUTER BRONZE | L36: - | M36: AKTIVASI | N36: 46069 | O36: 46054 | P36: [311601002593] BADAN KEUANGAN DAERAH KOTA SINGKAWANG - JL. FIRDAUS | R36: - | S36: Down | T36: Digunakan -perangkat nyala -OPM ke perangkat -2.56dB - OPM ke HO -7.78 dB | U36: KALIMANTAN | V36: KALIMANTAN BARAT | W36: - | X36: - | Y36: - | Z36: 26671 | AA36: 200005426 | AB36: 140001941 | AC36: - | AD36: - | AE36: AKTIF | AF36: UNISOLIR | AG36: 0,00 | AH36: 0,00 | AI36: - | AJ36: 90400818 | AK36: --/--/-- | AL36: 2026/03/01 - 2026/03/31 | AM36: PREPAID | AN36: PRORATE | AO36: SUBSCRIBE | AP36: 1 - BULAN | AQ36: KALIMANTAN | AR36: KALIMANTAN BARAT | AS36: GOVERNMENT | AT36: GOVERNMENT | AU36: KALIMANTAN | AV36: KALIMANTAN TIMUR
A37: 36 | B37: 311490003398 | C37: 311601002745 | D37: DISKOMINFO KOTA SINGKAWANG | E37: 00.280.304.7-702.000 | F37: EP-01KEQYM0J4BDVEGR7W4RWTXKST | G37: 2026/02/16 - 2026/12/31 | H37: - | I37: INTERNET DEDICATED DAN JARINGAN METRONET | J37: MANAGE SERVICE ROUTER | K37: MANAGE SERVICE ROUTER BRONZE | L37: - | M37: AKTIVASI | N37: 46069 | O37: 46054 | P37: [311601002594] DISHUB KIR SINGKAWANG - JL. KRIDASANA | R37: - | S37: Down | T37: Digunakan -Hasil OPM kearah HO Low - OPM ke arah rb2011 -3.37 -OTDR putus 157.6 m dari user - Perangkat nyala -ada UTP yang kecolok, user masih mau pakai untuk backup | U37: KALIMANTAN | V37: KALIMANTAN BARAT | W37: - | X37: - | Y37: - | Z37: 26671 | AA37: 200005426 | AB37: 140001941 | AC37: - | AD37: - | AE37: AKTIF | AF37: UNISOLIR | AG37: 0,00 | AH37: 0,00 | AI37: - | AJ37: 90460032 | AK37: --/--/-- | AL37: 2026/03/01 - 2026/03/31 | AM37: PREPAID | AN37: PRORATE | AO37: SUBSCRIBE | AP37: 1 - BULAN | AQ37: KALIMANTAN | AR37: KALIMANTAN BARAT | AS37: GOVERNMENT | AT37: GOVERNMENT | AU37: KALIMANTAN | AV37: KALIMANTAN TIMUR
... A63: 62 | B63: 311490003398 | C63: 311601002767 | D63: - | E63: 00.280.304.7-702.000 | F63: EP-01KEQYM0J4BDVEGR7W4RWTXKST | G63: 2026/02/16 - 2026/12/31 | H63: - | I63: INTERNET DEDICATED DAN JARINGAN METRONET | J63: MANAGE SERVICE ROUTER | K63: MANAGE SERVICE ROUTER BRONZE | L63: - | M63: AKTIVASI | N63: 46069 | O63: 46054 | P63: [311601002620] KANTOR CAMAT SINGKAWANG UTARA - JL. SINKA PERMAI | R63: - | S63: Down | T63: Perangkat Ada | U63: KALIMANTAN | V63: KALIMANTAN BARAT | W63: - | X63: - | Y63: - | Z63: 26671 | AA63: 200005426 | AB63: 140001941 | AC63: - | AD63: - | AE63: AKTIF | AF63: UNISOLIR | AG63: 0,00 | AH63: 0,00 | AI63: - | AJ63: 90410553 | AK63: --/--/-- | AL63: 2026/03/01 - 2026/03/31 | AM63: PREPAID | AN63: PRORATE | AO63: SUBSCRIBE | AP63: 1 - BULAN | AQ63: KALIMANTAN | AR63: KALIMANTAN BARAT | AS63: GOVERNMENT | AT63: GOVERNMENT | AU63: KALIMANTAN | AV63: KALIMANTAN TIMUR
A64: 63 | B64: 311490003398 | C64: 311202004670 | D64: DISKOMINFO KOTA SINGKAWANG | E64: 00.280.304.7-702.000 | F64: EP-01KEQYM0J4BDVEGR7W4RWTXKST | G64: 2026/02/16 - 2026/12/31 | H64: - | I64: INTERNET DEDICATED DAN JARINGAN METRONET | J64: METRONET | K64: METRONET | L64: - | M64: AKTIVASI | N64: 46069 | O64: 46054 | P64: [311202004349] BADAN PERENCANAAN DAN PEMBANGUNAN - JL. PELITA | Q64: RKAL-DISKOMINFO.KOTA.SINGKAWANG-ZYXEL.MGS3520-CPE-02 | R64: e 0/0/6 | S64: Up | T64: ok | U64: KALIMANTAN | V64: KALIMANTAN BARAT | W64: DISKOMINFO KOTA SINGKAWANG - JL. AHMAD YANI NO. 76 | X64: KALIMANTAN | Y64: KALIMANTAN BARAT | Z64: 26671 | AA64: 200005426 | AB64: 140001941 | AC64: - | AD64: - | AE64: AKTIF | AF64: UNISOLIR | AG64: 0,00 | AH64: 0,00 | AI64: - | AJ64: 90443543 | AK64: --/--/-- | AL64: 2026/03/01 - 2026/03/31 | AM64: PREPAID | AN64: PRORATE | AO64: SUBSCRIBE | AP64: 1 - BULAN | AQ64: KALIMANTAN | AR64: KALIMANTAN BARAT | AS64: GOVERNMENT | AT64: GOVERNMENT | AU64: KALIMANTAN | AV64: KALIMANTAN TIMUR
A65: 64 | B65: 311490003398 | C65: 311601002768 | D65: - | E65: 00.280.304.7-702.000 | F65: EP-01KEQYM0J4BDVEGR7W4RWTXKST | G65: 2026/02/16 - 2026/12/31 | H65: - | I65: INTERNET DEDICATED DAN JARINGAN METRONET | J65: MANAGE SERVICE ROUTER | K65: MANAGE SERVICE ROUTER BRONZE | L65: - | M65: AKTIVASI | N65: 46069 | O65: 46054 | P65: [311601002621] KANTOR KELURAHAN NYARUMKOP - JL. SINGKAWANG - BENGKAYANG | Q65: - | R65: - | S65: Up | T65: ok | U65: KALIMANTAN | V65: KALIMANTAN BARAT | W65: DISKOMINFO KOTA SINGKAWANG - JL. AHMAD YANI NO. 76 | X65: KALIMANTAN | Y65: KALIMANTAN BARAT | Z65: 26671 | AA65: 200005426 | AB65: 140001941 | AC65: - | AD65: - | AE65: AKTIF | AF65: UNISOLIR | AG65: 4151532 | AH65: 0,00 | AI65: - | AJ65: 90360815 | AK65: --/--/-- | AL65: 2026/03/01 - 2026/03/31 | AM65: PREPAID | AN65: PRORATE | AO65: SUBSCRIBE | AP65: 1 - BULAN | AQ65: KALIMANTAN | AR65: KALIMANTAN BARAT | AS65: GOVERNMENT | AT65: GOVERNMENT | AU65: KALIMANTAN | AV65: KALIMANTAN TIMUR
A66: 65 | B66: 311490003398 | C66: 311601002769 | D66: - | E66: 00.280.304.7-702.000 | F66: EP-01KEQYM0J4BDVEGR7W4RWTXKST | G66: 2026/02/16 - 2026/12/31 | H66: - | I66: INTERNET DEDICATED DAN JARINGAN METRONET | J66: MANAGE SERVICE ROUTER | K66: MANAGE SERVICE ROUTER BRONZE | L66: - | M66: AKTIVASI | N66: 46069 | O66: 46054 | P66: [311601002622] KECAMATAN SINGKAWANG SELATAN - JL. RAYA SEDAU NO. 16 | R66: - | S66: Up | T66: ok | U66: KALIMANTAN | V66: KALIMANTAN BARAT | W66: - | X66: - | Y66: - | Z66: 26671 | AA66: 200005426 | AB66: 140001941 | AC66: - | AD66: - | AE66: AKTIF | AF66: UNISOLIR | AG66: 3158559 | AH66: 0,00 | AI66: - | AJ66: 90378954 | AK66: --/--/-- | AL66: 2026/03/01 - 2026/03/31 | AM66: PREPAID | AN66: PRORATE | AO66: SUBSCRIBE | AP66: 1 - BULAN | AQ66: KALIMANTAN | AR66: KALIMANTAN BARAT | AS66: GOVERNMENT | AT66: GOVERNMENT | AU66: KALIMANTAN | AV66: KALIMANTAN TIMUR
A67: 66 | B67: 311490003398 | C67: 311202004696 | D67: DISKOMINFO KOTA SINGKAWANG | E67: 00.280.304.7-702.000 | F67: EP-01KEQYM0J4BDVEGR7W4RWTXKST | G67: 2026/02/16 - 2026/12/31 | H67: - | I67: INTERNET DEDICATED DAN JARINGAN METRONET | J67: METRONET | K67: METRONET | L67: - | M67: AKTIVASI | N67: 46069 | O67: 46054 | P67: [311202004389] CCTV NEW FASHION - JL. GM SITUT 26-22, CONDONG | Q67: RKAL-DISKOMINFO.KOTA.SINGKAWANG-ZYXEL.MGS3520-CPE-04 | R67: e 0/0/15 | S67: Up | T67: ok | U67: KALIMANTAN | V67: KALIMANTAN BARAT | W67: DISKOMINFO KOTA SINGKAWANG - JL. AHMAD YANI NO. 76 | X67: KALIMANTAN | Y67: KALIMANTAN BARAT | Z67: 26671 | AA67: 200005426 | AB67: 140001941 | AC67: - | AD67: - | AE67: AKTIF | AF67: UNISOLIR | AG67: 0,09 | AH67: 0,00 | AI67: - | AJ67: 90443546 | AK67: --/--/-- | AL67: 2026/03/01 - 2026/03/31 | AM67: PREPAID | AN67: PRORATE | AO67: SUBSCRIBE | AP67: 1 - BULAN | AQ67: KALIMANTAN | AR67: KALIMANTAN BARAT | AS67: GOVERNMENT | AT67: GOVERNMENT | AU67: KALIMANTAN | AV67: KALIMANTAN TIMUR
A68: 67 | B68: 311490003398 | C68: 311601002770 | D68: - | E68: 00.280.304.7-702.000 | F68: EP-01KEQYM0J4BDVEGR7W4RWTXKST | G68: 2026/02/16 - 2026/12/31 | H68: - | I68: INTERNET DEDICATED DAN JARINGAN METRONET | J68: MANAGE SERVICE ROUTER | K68: MANAGE SERVICE ROUTER BRONZE | L68: - | M68: AKTIVASI | N68: 46069 | O68: 46054 | P68: [311601002623] KANTOR KELURAHAN SAGATANI - | R68: - | S68: Up | T68: ok | U68: KALIMANTAN | V68: KALIMANTAN BARAT | W68: - | X68: - | Y68: - | Z68: 26671 | AA68: 200005426 | AB68: 140001941 | AC68: - | AD68: - | AE68: AKTIF | AF68: UNISOLIR | AG68: 18607153 | AH68: 0,00 | AI68: 0 | AJ68: 0 | AK68: --/--/-- | AL68: --/--/-- - --/--/-- | AM68: PREPAID | AN68: PRORATE | AO68: SUBSCRIBE | AP68: 1 - BULAN | AQ68: KALIMANTAN | AR68: KALIMANTAN BARAT | AS68: GOVERNMENT | AT68: GOVERNMENT | AU68: KALIMANTAN | AV68: KALIMANTAN TIMUR
A69: 68 | B69: 311490003398 | C69: 311401002730 | D69: DISKOMINFO KOTA SINGKAWANG | E69: 00.280.304.7-702.000 | F69: EP-01KEQYM0J4BDVEGR7W4RWTXKST | G69: 2026/02/16 - 2026/12/31 | H69: - | I69: INTERNET DEDICATED DAN JARINGAN METRONET | J69: INTERNET BROADBAND CORPORATE | K69: INTERNET BROADBAND CORPORATE IP PUBLIK | L69: - | M69: AKTIVASI | N69: 46069 | O69: 46054 | P69: DISKOMINFO KOTA SINGKAWANG - JL. AHMAD YANI NO. 76 | Q69: RKAL-DISKOMINFO.KOTA.SINGKAWANG-ZYXEL.MGS3520-CPE-04 | R69: e 0/0/24 | S69: Up | T69: ok | U69: KALIMANTAN | V69: KALIMANTAN BARAT | W69: - | X69: - | Y69: - | Z69: 26671 | AA69: 200005426 | AB69: 140001941 | AC69: - | AD69: - | AE69: AKTIF | AF69: UNISOLIR | AG69: 4144595 | AH69: 0,00 | AI69: - | AJ69: 90378201 | AK69: --/--/-- | AL69: 2026/03/01 - 2026/03/31 | AM69: PREPAID | AN69: PRORATE | AO69: SUBSCRIBE | AP69: 1 - BULAN | AQ69: KALIMANTAN | AR69: KALIMANTAN BARAT | AS69: GOVERNMENT | AT69: GOVERNMENT | AU69: KALIMANTAN | AV69: KALIMANTAN TIMUR
A70: 69 | B70: 311490003398 | C70: 311601002771 | D70: - | E70: 00.280.304.7-702.000 | F70: EP-01KEQYM0J4BDVEGR7W4RWTXKST | G70: 2026/02/16 - 2026/12/31 | H70: - | I70: INTERNET DEDICATED DAN JARINGAN METRONET | J70: MANAGE SERVICE ROUTER | K70: MANAGE SERVICE ROUTER BRONZE | L70: - | M70: AKTIVASI | N70: 46069 | O70: 46054 | P70: [311601002624] KANTOR KELURAHAN SANGGAU KULOR - JL. SANGGAU KULOR | R70: - | S70: Up | T70: ok | U70: KALIMANTAN | V70: KALIMANTAN BARAT | W70: - | X70: - | Y70: - | Z70: 26671 | AA70: 200005426 | AB70: 140001941 | AC70: - | AD70: - | AE70: AKTIF | AF70: UNISOLIR | AG70: 4970991 | AH70: 0,00 | AI70: - | AJ70: 90448224 | AK70: --/--/-- | AL70: 2026/03/01 - 2026/03/31 | AM70: PREPAID | AN70: PRORATE | AO70: SUBSCRIBE | AP70: 1 - BULAN | AQ70: KALIMANTAN | AR70: KALIMANTAN BARAT | AS70: GOVERNMENT | AT70: GOVERNMENT | AU70: KALIMANTAN | AV70: KALIMANTAN TIMUR
A71: 70 | B71: 311490003398 | C71: 311601002772 | D71: - | E71: 00.280.304.7-702.000 | F71: EP-01KEQYM0J4BDVEGR7W4RWTXKST | G71: 2026/02/16 - 2026/12/31 | H71: - | I71: INTERNET DEDICATED DAN JARINGAN METRONET | J71: MANAGE SERVICE ROUTER | K71: MANAGE SERVICE ROUTER BRONZE | L71: - | M71: AKTIVASI | N71: 46069 | O71: 46054 | P71: [311601002625] DINAS KEPENDUDUKAN DAN PENCATATAN SIPIL - JL DR. SUTOMO | R71: - | S71: Up | T71: ok | U71: KALIMANTAN | V71: KALIMANTAN BARAT | W71: - | X71: - | Y71: - | Z71: 26671 | AA71: 200005426 | AB71: 140001941 | AC71: - | AD71: - | AE71: AKTIF | AF71: UNISOLIR | AG71: 3097117 | AH71: 0,00 | AI71: - | AJ71: 90362616 | AK71: --/--/-- | AL71: 2026/03/01 - 2026/03/31 | AM71: PREPAID | AN71: PRORATE | AO71: SUBSCRIBE | AP71: 1 - BULAN | AQ71: KALIMANTAN | AR71: KALIMANTAN BARAT | AS71: GOVERNMENT | AT71: GOVERNMENT | AU71: KALIMANTAN | AV71: KALIMANTAN TIMUR
A72: 71 | B72: 311490003398 | C72: 311202004671 | D72: DISKOMINFO KOTA SINGKAWANG | E72: 00.280.304.7-702.000 | F72: EP-01KEQYM0J4BDVEGR7W4RWTXKST | G72: 2026/02/16 - 2026/12/31 | H72: - | I72: INTERNET DEDICATED DAN JARINGAN METRONET | J72: METRONET | K72: METRONET | L72: - | M72: AKTIVASI | N72: 46069 | O72: 46054 | P72: [311202004350] SEKRETARIAT DAERAH KOTA SINGKAWANG - JL. FIRDAUS NO.1 | Q72: RKAL-DISKOMINFO.KOTA.SINGKAWANG-ZYXEL.MGS3520-CPE-02 | R72: e 0/0/17 | S72: Up | T72: ok | U72: KALIMANTAN | V72: KALIMANTAN BARAT | W72: DISKOMINFO KOTA SINGKAWANG - JL. AHMAD YANI NO. 76 | X72: KALIMANTAN | Y72: KALIMANTAN BARAT | Z72: 26671 | AA72: 200005426 | AB72: 140001941 | AC72: - | AD72: - | AE72: AKTIF | AF72: UNISOLIR | AG72: 0,00 | AH72: 0,00 | AI72: - | AJ72: 90415458 | AK72: --/--/-- | AL72: 2026/03/01 - 2026/03/31 | AM72: PREPAID | AN72: PRORATE | AO72: SUBSCRIBE | AP72: 1 - BULAN | AQ72: KALIMANTAN | AR72: KALIMANTAN BARAT | AS72: GOVERNMENT | AT72: GOVERNMENT | AU72: KALIMANTAN | AV72: KALIMANTAN TIMUR
A73: 10 | B73: 311490003398 | C73: 311202004672 | D73: DISKOMINFO KOTA SINGKAWANG | E73: 00.280.304.7-702.000 | F73: EP-01KEQYM0J4BDVEGR7W4RWTXKST | G73: 2026/02/16 - 2026/12/31 | H73: - | I73: INTERNET DEDICATED DAN JARINGAN METRONET | J73: METRONET | K73: METRONET | L73: - | M73: AKTIVASI | N73: 46069 | O73: 46054 | P73: [311202004385] DINAS LINGKUNGAN HIDUP - JL. MERDEKA NO. 78 | Q73: RKAL-DISKOMINFO.KOTA.SINGKAWANG-ZYXEL.MGS3520-CPE-04 | R73: e 0/0/6 | S73: Down | T73: Perangkat ada | U73: KALIMANTAN | V73: KALIMANTAN BARAT | W73: DISKOMINFO KOTA SINGKAWANG - JL. AHMAD YANI NO. 76 | X73: KALIMANTAN | Y73: KALIMANTAN BARAT | Z73: 26671 | AA73: 200005426 | AB73: 140001941 | AC73: - | AD73: - | AE73: AKTIF | AF73: UNISOLIR | AG73: 0,00 | AH73: 0,00 | AI73: - | AJ73: 90428102 | AK73: --/--/-- | AL73: 2026/03/01 - 2026/03/31 | AM73: PREPAID | AN73: PRORATE | AO73: SUBSCRIBE | AP73: 1 - BULAN | AQ73: KALIMANTAN | AR73: KALIMANTAN BARAT | AS73: GOVERNMENT | AT73: GOVERNMENT | AU73: KALIMANTAN | AV73: KALIMANTAN TIMUR
A74: 11 | B74: 311490003398 | C74: 311202004673 | D74: DISKOMINFO KOTA SINGKAWANG | E74: 00.280.304.7-702.000 | F74: EP-01KEQYM0J4BDVEGR7W4RWTXKST | G74: 2026/02/16 - 2026/12/31 | H74: - | I74: INTERNET DEDICATED DAN JARINGAN METRONET | J74: METRONET | K74: METRONET | L74: - | M74: AKTIVASI | N74: 46069 | O74: 46054 | P74: [311202004335] PUSKESMAS SINGKAWANG TIMUR 1 - JL. RAYA PAJINTAN | Q74: RKAL-SHELTER.GI.SINGKAWANG-FH.S4830-CPE-01 | R74: ge1/0/8 | S74: Down | T74: Perangkat Hilang | U74: KALIMANTAN | V74: KALIMANTAN BARAT | W74: DISKOMINFO KOTA SINGKAWANG - JL. AHMAD YANI NO. 76 | X74: KALIMANTAN | Y74: KALIMANTAN BARAT | Z74: 26671 | AA74: 200005426 | AB74: 140001941 | AC74: - | AD74: - | AE74: AKTIF | AF74: UNISOLIR | AG74: 0,00 | AH74: 0,00 | AI74: - | AJ74: 90460019 | AK74: --/--/-- | AL74: 2026/03/01 - 2026/03/31 | AM74: PREPAID | AN74: PRORATE | AO74: SUBSCRIBE | AP74: 1 - BULAN | AQ74: KALIMANTAN | AR74: KALIMANTAN BARAT | AS74: GOVERNMENT | AT74: GOVERNMENT | AU74: KALIMANTAN | AV74: KALIMANTAN TIMUR
A75: 12 | B75: 311490003398 | C75: 311202004674 | D75: DISKOMINFO KOTA SINGKAWANG | E75: 00.280.304.7-702.000 | F75: EP-01KEQYM0J4BDVEGR7W4RWTXKST | G75: 2026/02/16 - 2026/12/31 | H75: - | I75: INTERNET DEDICATED DAN JARINGAN METRONET | J75: METRONET | K75: METRONET | L75: - | M75: AKTIVASI | N75: 46069 | O75: 46054 | P75: [311202004336] PUSKESMAS SINGKAWANG UTARA 1 - JL. RATU SEPUDAK | Q75: RKAL-SHELTER.GI.SINGKAWANG-FH.S4830-CPE-02 | R75: ge1/0/6 | S75: Down | T75: Perangkat Hilang | U75: KALIMANTAN | V75: KALIMANTAN BARAT | W75: DISKOMINFO KOTA SINGKAWANG - JL. AHMAD YANI NO. 76 | X75: KALIMANTAN | Y75: KALIMANTAN BARAT | Z75: 26671 | AA75: 200005426 | AB75: 140001941 | AC75: - | AD75: - | AE75: AKTIF | AF75: UNISOLIR | AG75: 0,00 | AH75: 0,00 | AI75: - | AJ75: 90360139 | AK75: --/--/-- | AL75: 2026/03/01 - 2026/03/31 | AM75: PREPAID | AN75: PRORATE | AO75: SUBSCRIBE | AP75: 1 - BULAN | AQ75: KALIMANTAN | AR75: KALIMANTAN BARAT | AS75: GOVERNMENT | AT75: GOVERNMENT | AU75: KALIMANTAN | AV75: KALIMANTAN TIMUR
A76: 13 | B76: 311490003398 | C76: 311202004675 | D76: DISKOMINFO KOTA SINGKAWANG | E76: 00.280.304.7-702.000 | F76: EP-01KEQYM0J4BDVEGR7W4RWTXKST | G76: 2026/02/16 - 2026/12/31 | H76: - | I76: INTERNET DEDICATED DAN JARINGAN METRONET | J76: METRONET | K76: METRONET | L76: - | M76: AKTIVASI | N76: 46069 | O76: 46054 | P76: [311202004337] PUSKESMAS SINGKAWANG BARAT 2 - JL. YOHANA | Q76: RKAL-SHELTER.GI.SINGKAWANG-FH.S4830-CPE-01 | R76: ge1/0/1 | S76: Down | T76: Perangkat Hilang | U76: KALIMANTAN | V76: KALIMANTAN BARAT | W76: DISKOMINFO KOTA SINGKAWANG - JL. AHMAD YANI NO. 76 | X76: KALIMANTAN | Y76: KALIMANTAN BARAT | Z76: 26671 | AA76: 200005426 | AB76: 140001941 | AC76: - | AD76: - | AE76: AKTIF | AF76: UNISOLIR | AG76: 0,00 | AH76: 0,00 | AI76: - | AJ76: 90460021 | AK76: --/--/-- | AL76: 2026/03/01 - 2026/03/31 | AM76: PREPAID | AN76: PRORATE | AO76: SUBSCRIBE | AP76: 1 - BULAN | AQ76: KALIMANTAN | AR76: KALIMANTAN BARAT | AS76: GOVERNMENT | AT76: GOVERNMENT | AU76: KALIMANTAN | AV76: KALIMANTAN TIMUR
...

Sheet Sheet2
A1: ID PELANGGAN | B1: SERVICE ID | C1: NAMA PELANGGAN | D1: LAYANAN | E1: ALAMAT TERMINATING | F1: Jarak (m) | G1: Koordinat | H1: ESTIMASI HARGA | J1: TOTAL RINCIAN | K1: SELISIH | L1: KETERANGAN
A2: 311490003398 | B2: 311202004727 | C2: DISKOMINFO KOTA SINGKAWANG | D2: METRONET | E2: [311202004340] PUSKESMAS SINGKAWANG TENGAH 2 - JL AHMAD YANI | F2: 500 | G2: 0.9084563394553016, 109.01020051628777 (IFT) | J2: =SUMIFS('Rincian RAB'!$J$2:$J$254,'Rincian RAB'!$B$2:$B$254,$B2) -> 0 | K2: =IF(J2=0,"",H2-J2)
A3: 311490003398 | B3: 311202004728 | C3: DISKOMINFO KOTA SINGKAWANG | D3: METRONET | E3: [311202004359] DINAS KESEHATAN DAN KELUARGA BERENCANA - JL. ALIANYANG NO. 7 | F3: 300 | G3: 0.9066394358482518, 108.97867828038373 (IFT) | J3: =SUMIFS('Rincian RAB'!$J$2:$J$254,'Rincian RAB'!$B$2:$B$254,$B3) -> 0 | K3: =IF(J3=0,"",H3-J3)
A4: 311490003398 | B4: 311202004731 | C4: DISKOMINFO KOTA SINGKAWANG | D4: METRONET | E4: [311202004355] CCTV SEI WIE - JL. ALIANYANG, SEI WEI | F4: 100 | G4: 0.92368, 108.98645 | H4: 10992508 | I4: 4600253989 | J4: =SUMIFS('Rincian RAB'!$J$2:$J$254,'Rincian RAB'!$B$2:$B$254,$B4) -> 10992508 | K4: =IF(J4=0,"",H4-J4) -> 0
A5: 311490003398 | B5: 311202004730 | C5: DISKOMINFO KOTA SINGKAWANG | D5: METRONET | E5: [311202004354] DINAS PERDAGANGAN, PERINDUSTRIAN, KOPERASI DAN UKM - JL. FIRDAUS | F5: 300 | G5: 0.9006988811285097, 108.98089358372515 | H5: 8885928 | I5: 4600065796 | J5: =SUMIFS('Rincian RAB'!$J$2:$J$254,'Rincian RAB'!$B$2:$B$254,$B5) -> 0 | K5: =IF(J5=0,"",H5-J5)
A6: 311490003398 | B6: 311202004732 | C6: DISKOMINFO KOTA SINGKAWANG | D6: METRONET | E6: [311202004356] DINAS PERHUBUNGAN - JL. TERMINAL INDUK SEI WIE | F6: 200 | G6: 0.9219230005101394, 108.98042408922747 (IFT) | J6: =SUMIFS('Rincian RAB'!$J$2:$J$254,'Rincian RAB'!$B$2:$B$254,$B6) -> 0 | K6: =IF(J6=0,"",H6-J6)
A7: 311490003398 | B7: 311202004682 | C7: DISKOMINFO KOTA SINGKAWANG | D7: METRONET | E7: [311202004357] CCTV HERMANSYAH - JL. S.M TSJAFIOEDDIN 17-51 | F7: 100 | G7: 0.90768, 108.98514 (IFT) | J7: =SUMIFS('Rincian RAB'!$J$2:$J$254,'Rincian RAB'!$B$2:$B$254,$B7) -> 0 | K7: =IF(J7=0,"",H7-J7)
A8: 311490003398 | B8: 311202004733 | C8: DISKOMINFO KOTA SINGKAWANG | D8: METRONET | E8: [311202004351] SEKRETARIAT DPRD - JL. FIRDAUS | F8: 200 | G8: 0.9035417135563482, 108.9782642837502 | J8: =SUMIFS('Rincian RAB'!$J$2:$J$254,'Rincian RAB'!$B$2:$B$254,$B8) -> 0 | K8: =IF(J8=0,"",H8-J8)
A9: 311490003398 | B9: 311202004734 | C9: DISKOMINFO KOTA SINGKAWANG | D9: METRONET | E9: [311202004352] DINAS PENANAMAN MODAL DAN TENAGA KERJA - JL. BKLI KOMPLEK LLK-UKM | F9: 300 | G9: 0.8973369548768787, 108.98090390549905 | H9: 9313769 | I9: 4600066257 | J9: =SUMIFS('Rincian RAB'!$J$2:$J$254,'Rincian RAB'!$B$2:$B$254,$B9) -> 9313769 | K9: =IF(J9=0,"",H9-J9) -> 0
A10: 311490003398 | B10: 311202004729 | C10: DISKOMINFO KOTA SINGKAWANG | D10: METRONET | E10: [311202004360] KANTOR KELURAHAN SEJANGKUNG - JL. RAYA SEJANGKUNG | F10: 2300 | G10: 0.8804835029269873, 109.10181111005035 (IFT) | J10: =SUMIFS('Rincian RAB'!$J$2:$J$254,'Rincian RAB'!$B$2:$B$254,$B10) -> 0 | K10: =IF(J10=0,"",H10-J10)
A11: 311490003398 | B11: 311202004684 | C11: DISKOMINFO KOTA SINGKAWANG | D11: METRONET | E11: [311202004361] KANTOR KELURAHAN PANGMILANG - PANGMILANG | F11: 500 | G11: 0.8259123249687154, 108.98599370816106 (IFT) | J11: =SUMIFS('Rincian RAB'!$J$2:$J$254,'Rincian RAB'!$B$2:$B$254,$B11) -> 0 | K11: =IF(J11=0,"",H11-J11)
A12: 311490003398 | B12: 311202004685 | C12: DISKOMINFO KOTA SINGKAWANG | D12: METRONET | E12: [311202004362] KANTOR KELURAHAN SEDAU - JL. RAYA SEDAU | F12: 250 | G12: 0.8401540320873829, 108.91355147462126 (IFT) | J12: =SUMIFS('Rincian RAB'!$J$2:$J$254,'Rincian RAB'!$B$2:$B$254,$B12) -> 0 | K12: =IF(J12=0,"",H12-J12)
A13: 311490003398 | B13: 311202004686 | C13: DISKOMINFO KOTA SINGKAWANG | D13: METRONET | E13: [311202004363] KANTOR KELURAHAN SAGATANI - JL. SAGATANI | F13: 700 | G13: 0.8040674642723963, 109.02443349080073 (IFT) | J13: =SUMIFS('Rincian RAB'!$J$2:$J$254,'Rincian RAB'!$B$2:$B$254,$B13) -> 0 | K13: =IF(J13=0,"",H13-J13)
A14: 311490003398 | B14: 311202004687 | C14: DISKOMINFO KOTA SINGKAWANG | D14: METRONET | E14: [311202004364] KANTOR KELURAHAN NYARUMKOP - NYAR UMKOP | F14: 700 | G14: 0.8773174753062917, 109.06207247731909 (IFT) | J14: =SUMIFS('Rincian RAB'!$J$2:$J$254,'Rincian RAB'!$B$2:$B$254,$B14) -> 0 | K14: =IF(J14=0,"",H14-J14)
A15: 311490003398 | B15: 311202004688 | C15: DISKOMINFO KOTA SINGKAWANG | D15: METRONET | E15: [311202004365] KANTOR KELURAHAN MAYASOPA - JL. SEBAKUN | F15: 1100 | G15: 0.8829885213647275, 109.11933113151379 | H15: 9923296 | I15: 4600068576 | J15: =SUMIFS('Rincian RAB'!$J$2:$J$254,'Rincian RAB'!$B$2:$B$254,$B15) -> 21291626 | K15: =IF(J15=0,"",H15-J15) -> -11368330
A16: 311490003398 | B16: 311202004689 | C16: DISKOMINFO KOTA SINGKAWANG | D16: METRONET | E16: [311202004366] KANTOR KELURAHAN BAGAK SAHWA - JL. SINGKAWANG - BENGKAYANG | F16: 150 | G16: 0.86785961094312, 109.09402048977532 | H16: 9755947 | I16: 4600068992 | J16: =SUMIFS('Rincian RAB'!$J$2:$J$254,'Rincian RAB'!$B$2:$B$254,$B16) -> 9778725 | K16: =IF(J16=0,"",H16-J16) -> -22778
A17: 311490003398 | B17: 311202004723 | C17: DISKOMINFO KOTA SINGKAWANG | D17: METRONET | E17: [311202004367] KANTOR KELURAHAN SANGGAU KULOR - JL. SANGGAU KULOR | F17: 3200 | G17: 0.8640142749427572, 109.01608070396233 (IFT) | J17: =SUMIFS('Rincian RAB'!$J$2:$J$254,'Rincian RAB'!$B$2:$B$254,$B17) -> 0 | K17: =IF(J17=0,"",H17-J17)
A18: 311490003398 | B18: 311202004690 | C18: DISKOMINFO KOTA SINGKAWANG | D18: METRONET | E18: [311202004369] KANTOR CAMAT SINGKAWANG UTARA - SUNGAI BULAN | F18: 500 | G18: 0.9441835275235747, 109.01611195894354 (IFT) | J18: =SUMIFS('Rincian RAB'!$J$2:$J$254,'Rincian RAB'!$B$2:$B$254,$B18) -> 0 | K18: =IF(J18=0,"",H18-J18)
A19: 311490003398 | B19: 311202004691 | C19: DISKOMINFO KOTA SINGKAWANG | D19: METRONET | E19: [311202004370] KECAMATAN SINGKAWANG SELATAN - JL. RAYA SEDAU NO. 16 | F19: 200 | G19: 0.865161197802931, 108.9296450785621 (IFT) | J19: =SUMIFS('Rincian RAB'!$J$2:$J$254,'Rincian RAB'!$B$2:$B$254,$B19) -> 0 | K19: =IF(J19=0,"",H19-J19)
A20: 311490003398 | B20: 311202004721 | C20: DISKOMINFO KOTA SINGKAWANG | D20: METRONET | E20: [311202004371] KANTOR CAMAT SINGKAWANG TENGAH - JL. PAHLAWAN NO. 1 | F20: 500 | G20: 0.9043151829941108, 109.00634659656168 (IFT) | J20: =SUMIFS('Rincian RAB'!$J$2:$J$254,'Rincian RAB'!$B$2:$B$254,$B20) -> 0 | K20: =IF(J20=0,"",H20-J20)
A21: 311490003398 | B21: 311202004722 | C21: DISKOMINFO KOTA SINGKAWANG | D21: METRONET | E21: [311202004372] KANTOR CAMAT SINGKAWANG TIMUR - JL. RAYA PAJINTAN | F21: 900 | G21: 0.8816151731106957, 109.04808965523519 (IFT) | J21: =SUMIFS('Rincian RAB'!$J$2:$J$254,'Rincian RAB'!$B$2:$B$254,$B21) -> 0 | K21: =IF(J21=0,"",H21-J21)
A22: 311490003398 | B22: 311202004719 | C22: DISKOMINFO KOTA SINGKAWANG | D22: METRONET | E22: [311202004375] KANTOR KELURAHAN SEMELAGI KECIL. - JL. DEMANG AKUB | F22: 3200 | G22: 1.0021824865959554, 109.04817492554486 (IFT) | J22: =SUMIFS('Rincian RAB'!$J$2:$J$254,'Rincian RAB'!$B$2:$B$254,$B22) -> 0 | K22: =IF(J22=0,"",H22-J22)
A23: 311490003398 | B23: 311202004693 | C23: DISKOMINFO KOTA SINGKAWANG | D23: METRONET | E23: [311202004377] CCTV SIMPANG PU - JL JEND AHMAD YANI | F23: 100 | G23: 0.89158, 108.96608 | H23: 10058200 | I23: 4600091887 | J23: =SUMIFS('Rincian RAB'!$J$2:$J$254,'Rincian RAB'!$B$2:$B$254,$B23) -> 9821188 | K23: =IF(J23=0,"",H23-J23) -> 237012
A24: 311490003398 | B24: 311202004706 | C24: DISKOMINFO KOTA SINGKAWANG | D24: METRONET | E24: [311202004383] CCTV PERBATASAN SAMBAS - JL. PASAR SEMELAGI BESAR | F24: 300 | G24: 0.9959, 108.98708 (IFT) | J24: =SUMIFS('Rincian RAB'!$J$2:$J$254,'Rincian RAB'!$B$2:$B$254,$B24) -> 0 | K24: =IF(J24=0,"",H24-J24)
A25: 311490003398 | B25: 311202004670 | C25: DISKOMINFO KOTA SINGKAWANG | D25: METRONET | E25: [311202004349] BADAN PERENCANAAN DAN PEMBANGUNAN - JL. PELITA | F25: 400 | G25: -0.022578960555593285, 109.33843578753121 | H25: 9053277 | J25: =SUMIFS('Rincian RAB'!$J$2:$J$254,'Rincian RAB'!$B$2:$B$254,$B25) -> 0 | K25: =IF(J25=0,"",H25-J25)
A26: 311490003398 | B26: 311202004696 | C26: DISKOMINFO KOTA SINGKAWANG | D26: METRONET | E26: [311202004389] CCTV NEW FASHION - JL. GM SITUT 26-22, CONDONG | F26: 150 | G26: 0.9088, 108.99076 | H26: 15240931 | I26: 4600071418 | J26: =SUMIFS('Rincian RAB'!$J$2:$J$254,'Rincian RAB'!$B$2:$B$254,$B26) -> 13033706 | K26: =IF(J26=0,"",H26-J26) -> 2207225
A27: 311490003398 | B27: 311202004671 | C27: DISKOMINFO KOTA SINGKAWANG | D27: METRONET | E27: [311202004350] SEKRETARIAT DAERAH KOTA SINGKAWANG - JL. FIRDAUS NO.1 | F27: 200 | G27: 0.904403363851908, 108.9773835086288 | J27: =SUMIFS('Rincian RAB'!$J$2:$J$254,'Rincian RAB'!$B$2:$B$254,$B27) -> 0 | K27: =IF(J27=0,"",H27-J27)
A28: 311490003398 | B28: 311202004672 | C28: DISKOMINFO KOTA SINGKAWANG | D28: METRONET | E28: [311202004385] DINAS LINGKUNGAN HIDUP - JL. MERDEKA NO. 78 | F28: 400 | G28: 0.9127931411113182, 108.99084902483739 | H28: =10238479+17650829 -> 27889308 | I28: 4600069008/4600071153 | J28: =SUMIFS('Rincian RAB'!$J$2:$J$254,'Rincian RAB'!$B$2:$B$254,$B28) -> 28571117 | K28: =IF(J28=0,"",H28-J28) -> -681809
A29: 311490003398 | B29: 311202004673 | C29: DISKOMINFO KOTA SINGKAWANG | D29: METRONET | E29: [311202004335] PUSKESMAS SINGKAWANG TIMUR 1 - JL. RAYA PAJINTAN | F29: 600 | G29: 0.876549197599874, 109.04152182781397 | H29: =7211642+12411562 -> 19623204 | I29: 4600115590 | J29: =SUMIFS('Rincian RAB'!$J$2:$J$254,'Rincian RAB'!$B$2:$B$254,$B29) -> 19623204 | K29: =IF(J29=0,"",H29-J29) -> 0 | L29: No. PO: 4600267902
A30: 311490003398 | B30: 311202004674 | C30: DISKOMINFO KOTA SINGKAWANG | D30: METRONET | E30: [311202004336] PUSKESMAS SINGKAWANG UTARA 1 - JL. RATU SEPUDAK | F30: 350 | G30: 0.9759804689605267, 108.98714211484469 | H30: 52126437 | I30: 4600113286 | J30: =SUMIFS('Rincian RAB'!$J$2:$J$254,'Rincian RAB'!$B$2:$B$254,$B30) -> 52126437 | K30: =IF(J30=0,"",H30-J30) -> 0
A31: 311490003398 | B31: 311202004675 | C31: DISKOMINFO KOTA SINGKAWANG | D31: METRONET | E31: [311202004337] PUSKESMAS SINGKAWANG BARAT 2 - JL. YOHANA | F31: 200 | G31: 0.8961413118629321, 108.98149601687484 (IFT) | J31: =SUMIFS('Rincian RAB'!$J$2:$J$254,'Rincian RAB'!$B$2:$B$254,$B31) -> 0 | K31: =IF(J31=0,"",H31-J31)
A32: 311490003398 | B32: 311202004676 | C32: DISKOMINFO KOTA SINGKAWANG | D32: METRONET | E32: [311202004341] PUSKESMAS SINGKAWANG SELATAN 1 - JL. SEDAU | F32: 350 | G32: 0.8400251924367828, 108.91416115022311 | H32: 16286258 | I32: 4600109739 | J32: =SUMIFS('Rincian RAB'!$J$2:$J$254,'Rincian RAB'!$B$2:$B$254,$B32) -> 16286258 | K32: =IF(J32=0,"",H32-J32) -> 0
A33: 311490003398 | B33: 311202004677 | C33: DISKOMINFO KOTA SINGKAWANG | D33: METRONET | E33: [311202004345] CCTV BUNDARAN AI - DISKOMINFO KOTA SINGKAWANG - JL. AHMAD YANI | F33: 450 | G33: 0.89251, 108.96386 | H33: 8664926 | I33: 4600253924 | J33: =SUMIFS('Rincian RAB'!$J$2:$J$254,'Rincian RAB'!$B$2:$B$254,$B33) -> 8664926 | K33: =IF(J33=0,"",H33-J33) -> 0
A34: 311490003398 | B34: 311202004678 | C34: DISKOMINFO KOTA SINGKAWANG | D34: METRONET | E34: [311202004346] PUSKESMAS SINGKAWANG TIMUR 2 - JL. RAYA SINGKAWANG-BENGKAYANG | F34: 500 | G34: 0.8789153011546297, 109.11785379932911 (IFT) | J34: =SUMIFS('Rincian RAB'!$J$2:$J$254,'Rincian RAB'!$B$2:$B$254,$B34) -> 0 | K34: =IF(J34=0,"",H34-J34)
A35: 311490003398 | B35: 311202004679 | C35: DISKOMINFO KOTA SINGKAWANG | D35: METRONET | E35: [311202004347] BKPSDM - JL. FIRDAUS, PASIRAN | F35: 300 | G35: 0.9046976123361817, 108.97677230349669 | J35: =SUMIFS('Rincian RAB'!$J$2:$J$254,'Rincian RAB'!$B$2:$B$254,$B35) -> 0 | K35: =IF(J35=0,"",H35-J35)
A36: 311490003398 | B36: 311202004680 | C36: DISKOMINFO KOTA SINGKAWANG | D36: METRONET | E36: [311202004348] INSPEKTORAT - JL. ALIANYANG NO.1 | F36: 150 | G36: 0.9049977290739513, 108.9770542497433 | J36: =SUMIFS('Rincian RAB'!$J$2:$J$254,'Rincian RAB'!$B$2:$B$254,$B36) -> 0 | K36: =IF(J36=0,"",H36-J36)
A37: 311490003398 | B37: 311202004681 | C37: DISKOMINFO KOTA SINGKAWANG | D37: METRONET | E37: [311202004353] DISPORA - JL. KRIDASANA, SINGKAWANG BARAT | F37: 300 | G37: 0.8966673218984869, 108.98689409255027 | H37: =10397685+21065705 -> 31463390 | I37: PA/ACT/1908/1678/TER DISKOMINFO KOTA SINGKAWANG (Stadion Kridasana Kota Singkawang) Jl. Kridasana,Pasiran ,Kota Singkawang ,Kalimantan Barat ,Indonesia ,79123 101920B30708 | J37: =SUMIFS('Rincian RAB'!$J$2:$J$254,'Rincian RAB'!$B$2:$B$254,$B37) -> 0 | K37: =IF(J37=0,"",H37-J37) | L37: No. PO: 4600065914
A38: 311490003398 | B38: 311202004683 | C38: DISKOMINFO KOTA SINGKAWANG | D38: METRONET | E38: [311202004358] DINAS PUPR - JL. PASIRAN, SINGKAWANG BARAT | F38: 100 | G38: 0.8911946694276672, 108.96813230280699 | J38: =SUMIFS('Rincian RAB'!$J$2:$J$254,'Rincian RAB'!$B$2:$B$254,$B38) -> 0 | K38: =IF(J38=0,"",H38-J38)
A39: 311490003398 | B39: 311202004692 | C39: DISKOMINFO KOTA SINGKAWANG | D39: METRONET | E39: [311202004373] RUMAH DINAS WAKIL WALIKOTA. - JL. GUNUNG POTENG | F39: 300 | G39: 0.9019601547475674, 108.97728499080692 | J39: =SUMIFS('Rincian RAB'!$J$2:$J$254,'Rincian RAB'!$B$2:$B$254,$B39) -> 0 | K39: =IF(J39=0,"",H39-J39)
A40: 311490003398 | B40: 311202004694 | C40: DISKOMINFO KOTA SINGKAWANG | D40: METRONET | E40: [311202004378] CCTV SIMPANG POLRES LAMA - JL. GM SITUT | F40: 150 | G40: 0.89993, 108.98581 | H40: 16030924 | I40: 4600091884 | J40: =SUMIFS('Rincian RAB'!$J$2:$J$254,'Rincian RAB'!$B$2:$B$254,$B40) -> 14937629 | K40: =IF(J40=0,"",H40-J40) -> 1093295
...

Sheet Rincian RAB
A1: NO | B1: SERVICE ID | C1: LOKASI | D1: NO. PO | E1: KODE | F1: URAIAN PEKERJAAN | G1: VOLUME | H1: SATUAN | I1: HARGA SATUAN | J1: JUMLAH
A2: 1 | B2: 311202004731 | C2: CCTV SEI WIE - JL. ALIANYANG, SEI WEI | D2: 4600253989 | E2: 3003571 | F2: Survey jalur kabel incl.Spotting GPS Blk | G2: 1 | H2: LOT | I2: 821630 | J2: =G2*I2 -> 821630
A3: 2 | B3: 311202004731 | C3: CCTV SEI WIE - JL. ALIANYANG, SEI WEI | D3: 4600253989 | E3: 3003572 | F3: Penarikan FOC ADSS Short Span Blk | G3: 1050 | H3: M | I3: 4094 | J3: =G3*I3 -> 4298700
A4: 3 | B4: 311202004731 | C4: CCTV SEI WIE - JL. ALIANYANG, SEI WEI | D4: 4600253989 | E4: 3003577 | F4: Jointing per core incl.labeling JB Blk | G4: 3 | H4: AU | I4: 47159 | J4: =G4*I4 -> 141477
A5: 4 | B5: 311202004731 | C5: CCTV SEI WIE - JL. ALIANYANG, SEI WEI | D5: 4600253989 | E5: 3003578 | F5: Tracing core (incl.Label Joint Box)Blk | G5: 4 | H5: AU | I5: 167349 | J5: =G5*I5 -> 669396
A6: 5 | B6: 311202004731 | C6: CCTV SEI WIE - JL. ALIANYANG, SEI WEI | D6: 4600253989 | E6: 3003579 | F6: OTDR per core Blk | G6: 2 | H6: AU | I6: 42495 | J6: =G6*I6 -> 84990
A7: 6 | B7: 311202004731 | C7: CCTV SEI WIE - JL. ALIANYANG, SEI WEI | D7: 4600253989 | E7: 3003581 | F7: Labeling Kabel (1 pole 2 label) Blk | G7: 22 | H7: U | I7: 11384 | J7: =G7*I7 -> 250448
A8: 7 | B8: 311202004731 | C8: CCTV SEI WIE - JL. ALIANYANG, SEI WEI | D8: 4600253989 | E8: 3003594 | F8: Instalasi Access Point (inc.Survey) Blk | G8: 1 | H8: AU | I8: 566072 | J8: =G8*I8 -> 566072
A9: 8 | B9: 311202004731 | C9: CCTV SEI WIE - JL. ALIANYANG, SEI WEI | D9: 4600253989 | E9: 3003598 | F9: Fitting Deadend, 6 - 48 core Blk | G9: 6 | H9: U | I9: 104353 | J9: =G9*I9 -> 626118
A10: 9 | B10: 311202004731 | C10: CCTV SEI WIE - JL. ALIANYANG, SEI WEI | D10: 4600253989 | E10: 3003599 | F10: Fitting Suspension, 6-48 core Blk | G10: 16 | H10: U | I10: 72382 | J10: =G10*I10 -> 1158112
A11: 10 | B11: 311202004731 | C11: CCTV SEI WIE - JL. ALIANYANG, SEI WEI | D11: 4600253989 | E11: 3003607 | F11: Patch Cord Single Mode 1 pasang 3m Blk | G11: 2 | H11: U | I11: 149131 | J11: =G11*I11 -> 298262
A12: 11 | B12: 311202004731 | C12: CCTV SEI WIE - JL. ALIANYANG, SEI WEI | D12: 4600253989 | E12: 3003618 | F12: Joint Box 24 Core Blk | G12: 1 | H12: U | I12: 1089630 | J12: =G12*I12 -> 1089630
A13: 12 | B13: 311202004731 | C13: CCTV SEI WIE - JL. ALIANYANG, SEI WEI | D13: 4600253989 | E13: 3003623 | F13: ODF Wall Mounted 6 Core(tipe SC upc)Blk | G13: 1 | H13: U | I13: 987673 | J13: =G13*I13 -> 987673
... A96: 95 | B96: 311202004674 | C96: PUSKESMAS SINGKAWANG UTARA 1 - JL. RATU SEPUDAK | D96: 4600113286 | E96: 3003623 | F96: ODF Wall Mounted 6 Core(tipe SC upc)Blk | G96: 2 | H96: U | I96: 987673 | J96: =G96*I96 -> 1975346
A97: 96 | B97: 311202004674 | C97: PUSKESMAS SINGKAWANG UTARA 1 - JL. RATU SEPUDAK | D97: 4600113286 | F97: ODF Rack Mounted 48 Core Blk | G97: 1 | H97: U | I97: 4169830 | J97: =G97*I97 -> 4169830
A98: 97 | B98: 311202004674 | C98: PUSKESMAS SINGKAWANG UTARA 1 - JL. RATU SEPUDAK | D98: 4600113286 | E98: 3003660 | F98: Transportasi Luar Kota min2Drum150KM Blk | G98: 1 | H98: LOT | I98: 717970 | J98: =G98*I98 -> 717970
A99: 98 | B99: 311202004676 | C99: PUSKESMAS SINGKAWANG SELATAN 1 - JL. SEDAU | D99: 4600109739 | E99: 3003571 | F99: Survey jalur kabel incl.Spotting GPS Blk | G99: 1 | H99: LOT | I99: 821630 | J99: =G99*I99 -> 821630
A100: 99 | B100: 311202004676 | C100: PUSKESMAS SINGKAWANG SELATAN 1 - JL. SEDAU | D100: 4600109739 | E100: 3003572 | F100: Penarikan FOC ADSS Short Span Blk | G100: 1600 | H100: M | I100: 4094 | J100: =G100*I100 -> 6550400
A101: 100 | B101: 311202004676 | C101: PUSKESMAS SINGKAWANG SELATAN 1 - JL. SEDAU | D101: 4600109739 | E101: 3003577 | F101: Jointing per core incl.labeling JB Blk | G101: 6 | H101: AU | I101: 47159 | J101: =G101*I101 -> 282954
A102: 101 | B102: 311202004676 | C102: PUSKESMAS SINGKAWANG SELATAN 1 - JL. SEDAU | D102: 4600109739 | E102: 3003578 | F102: Tracing core (incl.Label Joint Box)Blk | G102: 4 | H102: AU | I102: 167349 | J102: =G102*I102 -> 669396
A103: 102 | B103: 311202004676 | C103: PUSKESMAS SINGKAWANG SELATAN 1 - JL. SEDAU | D103: 4600109739 | E103: 3003579 | F103: OTDR per core Blk | G103: 4 | H103: AU | I103: 42495 | J103: =G103*I103 -> 169980
A104: 103 | B104: 311202004676 | C104: PUSKESMAS SINGKAWANG SELATAN 1 - JL. SEDAU | D104: 4600109739 | E104: 3003581 | F104: Labeling Kabel (1 pole 2 label) Blk | G104: 29 | H104: U | I104: 11384 | J104: =G104*I104 -> 330136
A105: 104 | B105: 311202004676 | C105: PUSKESMAS SINGKAWANG SELATAN 1 - JL. SEDAU | D105: 4600109739 | E105: 3003594 | F105: Instalasi Access Point (inc.Survey) Blk | G105: 2 | H105: AU | I105: 566072 | J105: =G105*I105 -> 1132144
A106: 105 | B106: 311202004676 | C106: PUSKESMAS SINGKAWANG SELATAN 1 - JL. SEDAU | D106: 4600109739 | E106: 3003598 | F106: Fitting Deadend, 6 - 48 core Blk | G106: 14 | H106: U | I106: 104353 | J106: =G106*I106 -> 1460942
A107: 106 | B107: 311202004676 | C107: PUSKESMAS SINGKAWANG SELATAN 1 - JL. SEDAU | D107: 4600109739 | E107: 3003599 | F107: Fitting Suspension, 6-48 core Blk | G107: 15 | H107: U | I107: 72382 | J107: =G107*I107 -> 1085730
A108: 107 | B108: 311202004676 | C108: PUSKESMAS SINGKAWANG SELATAN 1 - JL. SEDAU | D108: 4600109739 | E108: 3003618 | F108: Joint Box 24 Core Blk | G108: 1 | H108: U | I108: 1089630 | J108: =G108*I108 -> 1089630
A109: 108 | B109: 311202004676 | C109: PUSKESMAS SINGKAWANG SELATAN 1 - JL. SEDAU | D109: 4600109739 | E109: 3003623 | F109: ODF Wall Mounted 6 Core(tipe SC upc)Blk | G109: 2 | H109: U | I109: 987673 | J109: =G109*I109 -> 1975346
... A180: 179 | B180: 311202004708 | C180: DINAS PERUMAHAN PEMUKIMAN DAN PERTANAHAN - JL. AHMAD YANI NOMOR 74 | D180: 4600071224 | E180: 3003622 | F180: ODF Rack Mounted 6 Core(tipe SC upc)Blk | G180: 1 | H180: U | I180: 988293 | J180: =G180*I180 -> 988293
A181: 180 | B181: 311202004708 | C181: DINAS PERUMAHAN PEMUKIMAN DAN PERTANAHAN - JL. AHMAD YANI NOMOR 74 | D181: 4600071224 | F181: ODF Rack Mounted 48 Core Blk | G181: 1 | H181: U | I181: 4169830 | J181: =G181*I181 -> 4169830
A182: 181 | B182: 311202004708 | C182: DINAS PERUMAHAN PEMUKIMAN DAN PERTANAHAN - JL. AHMAD YANI NOMOR 74 | D182: 4600071224 | E182: 3003660 | F182: Transportasi Luar Kota min2Drum150KM Blk | G182: 1 | H182: LOT | I182: 717970 | J182: =G182*I182 -> 717970
A183: 182 | B183: 311202004709 | C183: KANTOR KELURAHAN SETAPUK KECIL - JL. HAMID METALI | D183: 4600071237 | E183: 3003571 | F183: Survey jalur kabel incl.Spotting GPS Blk | G183: 1 | H183: LOT | I183: 821630 | J183: =G183*I183 -> 821630
A184: 183 | B184: 311202004709 | C184: KANTOR KELURAHAN SETAPUK KECIL - JL. HAMID METALI | D184: 4600071237 | E184: 3003572 | F184: Penarikan FOC ADSS Short Span Blk | G184: 2700 | H184: M | I184: 4094 | J184: =G184*I184 -> 11053800
A185: 184 | B185: 311202004709 | C185: KANTOR KELURAHAN SETAPUK KECIL - JL. HAMID METALI | D185: 4600071237 | E185: 3003577 | F185: Jointing per core incl.labeling JB Blk | G185: 1 | H185: AU | I185: 47159 | J185: =G185*I185 -> 47159
A186: 185 | B186: 311202004709 | C186: KANTOR KELURAHAN SETAPUK KECIL - JL. HAMID METALI | D186: 4600071237 | E186: 3003578 | F186: Tracing core (incl.Label Joint Box)Blk | G186: 1 | H186: AU | I186: 167349 | J186: =G186*I186 -> 167349
A187: 186 | B187: 311202004709 | C187: KANTOR KELURAHAN SETAPUK KECIL - JL. HAMID METALI | D187: 4600071237 | E187: 3003579 | F187: OTDR per core Blk | G187: 1 | H187: AU | I187: 42495 | J187: =G187*I187 -> 42495
